Workbook

Sheet Cover
A1: HAVELLS INDIA LIMITED
A2: Three-Statement Operating Model & Discounted Cash Flow Valuation
A4: Ticker | B4: NSE: HAVELLS | BSE: 517354
A5: Sector | B5: Electrical equipment / Fast-moving electrical goods (FMEG)
A6: Reporting basis | B6: STANDALONE (subsidiaries immaterial: standalone is ~99.7% of consolidated revenue)
A7: Units | B7: INR crore unless stated otherwise
A8: Fiscal year end | B8: 31 March
A9: Historical period | B9: FY2025A - FY2026A
A10: Forecast period | B10: FY2027E - FY2031E (5 years)
A12: Prepared by | B12: << YOUR NAME >>
A13: Date | B13: << DATE >>
A15: Primary source | B15: Havells India Ltd, Information Update on Financial Results for Q4 and FY ended 31 Mar 2026, filed with NSE/BSE 22 April 2026
A16: Secondary sources | B16: Annual Reports FY22-FY26; quarterly earnings call transcripts; RBI (G-Sec yield); NYU Stern / Damodaran (equity risk premium, unlevered betas)
A18: Colour convention | B18: BLUE = hardcoded input | BLACK = formula on this sheet | GREEN = link from another sheet | YELLOW FILL = assumption requiring written justification
A20: Disclaimer | B20: This model was built as an educational exercise. It is not investment research and is not a recommendation to buy or sell any security. All forward-looking figures are the author's own estimates.
A24: HOW TO USE
A25: 1. Open the 'Assumptions' tab. Every yellow cell is an input you own. Change one and the entire model recalculates.
A26: 2. 'Check' on the Balance Sheet tab must read zero in every column. If it does not, the model is broken - do not use the output.
A27: 3. Fill the yellow inputs on 'WACC' with figures you pulled yourself, on a date you record.
A28: 4. Read the DCF output alongside 'Sensitivity' - a single point estimate is not a valuation.
A29: 5. Record the reasoning behind every input in docs/assumptions_log.md. That document, not this file, is what you will be questioned on.

Sheet Assumptions
A1: ASSUMPTIONS
A2: Yellow cells are inputs. Justify each one in docs/assumptions_log.md before presenting this model.
A4: INR crore | B4: FY25A | C4: FY26A | D4: FY27E | E4: FY28E | F4: FY29E | G4: FY30E | H4: FY31E
A6: REVENUE GROWTH (YoY %)
A7: Switchgears | C7: =IF(IS!C9=0,0,IS!D9/IS!C9-1) -> 0.09 | D7: 0.09 | E7: 0.09 | F7: 0.09 | G7: 0.08 | H7: 0.08
A8: Cables | C8: =IF(IS!C10=0,0,IS!D10/IS!C10-1) -> 0.14 | D8: 0.14 | E8: 0.13 | F8: 0.12 | G8: 0.11 | H8: 0.1
A9: Lighting & Fixtures | C9: =IF(IS!C11=0,0,IS!D11/IS!C11-1) -> 0.03 | D9: 0.03 | E9: 0.04 | F9: 0.04 | G9: 0.04 | H9: 0.04
A10: Electrical Consumer Durables | C10: =IF(IS!C12=0,0,IS!D12/IS!C12-1) -> 0.08 | D10: 0.08 | E10: 0.09 | F10: 0.09 | G10: 0.08 | H10: 0.08
A11: Others (incl. solar) | C11: =IF(IS!C13=0,0,IS!D13/IS!C13-1) -> 0.22 | D11: 0.22 | E11: 0.2 | F11: 0.18 | G11: 0.15 | H11: 0.12
A12: Lloyd Consumer | C12: =IF(IS!C14=0,0,IS!D14/IS!C14-1) -> 0.12 | D12: 0.12 | E12: 0.14 | F12: 0.12 | G12: 0.1 | H12: 0.09
A13: Havells definition: Net Revenue less material cost, manufacturing variables, direct selling variables and depreciation.
A14: CONTRIBUTION MARGIN (% of segment revenue)
A15: Switchgears | B15: 0.379 | C15: 0.369 | D15: 0.372 | E15: 0.375 | F15: 0.375 | G15: 0.375 | H15: 0.375
A16: Cables | B16: 0.141 | C16: 0.169 | D16: 0.165 | E16: 0.163 | F16: 0.162 | G16: 0.16 | H16: 0.16
A17: Lighting & Fixtures | B17: 0.326 | C17: 0.323 | D17: 0.31 | E17: 0.31 | F17: 0.31 | G17: 0.31 | H17: 0.31
A18: Electrical Consumer Durables | B18: 0.238 | C18: 0.23 | D18: 0.233 | E18: 0.235 | F18: 0.235 | G18: 0.235 | H18: 0.235
A19: Others (incl. solar) | B19: 0.17 | C19: 0.162 | D19: 0.165 | E19: 0.168 | F19: 0.17 | G19: 0.17 | H19: 0.17
A20: Lloyd Consumer | B20: 0.135 | C20: 0.084 | D20: 0.1 | E20: 0.115 | F20: 0.125 | G20: 0.13 | H20: 0.13
A22: OPERATING & CASH FLOW DRIVERS
A23: Advertising & sales promotion (% of net revenue) | B23: 0.029 | C23: 0.027 | D23: 0.028 | E23: 0.028 | F23: 0.028 | G23: 0.028 | H23: 0.028
A24: Other SG&A (% of net revenue) | B24: 0.091 | C24: 0.092 | D24: 0.09 | E24: 0.09 | F24: 0.09 | G24: 0.09 | H24: 0.09
A25: Other income, net (INR cr) | B25: 259 | C25: 204 | D25: 220 | E25: 240 | F25: 260 | G25: 280 | H25: 300
A26: Effective tax rate | B26: 0.259 | C26: 0.234 | D26: 0.252 | E26: 0.252 | F26: 0.252 | G26: 0.252 | H26: 0.252
A27: Capital expenditure (% of net revenue) | B27: 0.035 | C27: 0.066 | D27: 0.05 | E27: 0.045 | F27: 0.04 | G27: 0.038 | H27: 0.035
A28: Depreciation & amortisation (% of net revenue) | B28: 0.018 | C28: 0.019 | D28: 0.02 | E28: 0.021 | F28: 0.022 | G28: 0.022 | H28: 0.023
A29: Inventory days (on net revenue) | B29: 67 | C29: 71 | D29: 71 | E29: 71 | F29: 71 | G29: 71 | H29: 71
A30: Debtor days (on net revenue) | B30: 21 | C30: 13 | D30: 15 | E30: 15 | F30: 15 | G30: 15 | H30: 15
A31: Creditor days (on net revenue) | B31: 51 | C31: 47 | D31: 47 | E31: 47 | F31: 47 | G31: 47 | H31: 47
A32: Dividend payout (% of net profit) | B32: 0.421 | C32: 0.368 | D32: 0.37 | E32: 0.37 | F32: 0.37 | G32: 0.37 | H32: 0.37
A33: Lease liability interest rate | B33: 0.08 | C33: 0.08 | D33: 0.08 | E33: 0.08 | F33: 0.08 | G33: 0.08 | H33: 0.08
A34: Lease payments (INR cr) | B34: 90 | C34: 90 | D34: 95 | E34: 100 | F34: 105 | G34: 110 | H34: 115
A36: VALUATION STATICS
A37: Diluted shares outstanding (crore) | B37: 62.7 | D37: Equity share capital INR 63cr at INR 1 face value. VERIFY against latest shareholding pattern.
A38: Current market price (INR / share) | B38: 1117 | D38: SOURCED 11-Sep-2026: market cap Rs 70,036 Cr / 62.7 Cr shares, bajajbroking.in intraday quote. Verify against a live quote before presenting -- Havells has moved several percent week to week this year.
A39: Terminal growth rate (g) | B39: 0.05 | D39: Must be below WACC and below long-run nominal GDP growth.
A40: Non-core investments carried to equity bridge (INR cr) | B40: 883 | D40: Goldi Solar stake: INR 600cr cost + INR 283cr unrealised fair value gain. Excluded from operating EBIT.
A41: Mid-year discounting convention (1 = on, 0 = off) | B41: 1 | D41: Cash arrives through the year, not on 31 March.

Sheet Historicals
A1: REPORTED HISTORICALS
A2: As reported. Do not link forecasts to this tab - it exists as an audit trail so a reader can tie the model back to the filing.
A3: Source: Havells India Ltd, Information Update on Financial Results, Q4 & FY ended 31 Mar 2026, filed with NSE/BSE 22 Apr 2026. Standalone. INR crore.
A5: INR crore | B5: FY25A | C5: FY26A | D5: FY27E | E5: FY28E | F5: FY29E | G5: FY30E | H5: FY31E
A6: PROFIT & LOSS
A7: Net revenue | B7: 21746 | C7: 22466
A8: Contribution | B8: 4343 | C8: 4458
A9: Add: depreciation / amortisation | B9: 399 | C9: 429
A10: Less: advertising & sales promotion | B10: 622 | C10: 602
A11: Less: other SG&A | B11: 1970 | C11: 2072
A12: EBITDA | B12: 2149 | C12: 2213
A13: Depreciation / amortisation | B13: 399 | C13: 429
A14: Other income, net | B14: 259 | C14: 204
A15: Fair value gain on financial asset (unrealised) | B15: 0 | C15: 283
A16: Exceptional items | B16: 0 | C16: -45
A17: Profit before tax | B17: 2009 | C17: 2226
A18: Tax | B18: 520 | C18: 520
A19: Net profit | B19: 1489 | C19: 1705
A21: SEGMENT REVENUE
A22: Switchgears | B22: 2395 | C22: 2585
A23: Cables | B23: 7184 | C23: 8677
A24: Lighting & Fixtures | B24: 1653 | C24: 1655
A25: Electrical Consumer Durables | B25: 4011 | C25: 3874
A26: Others | B26: 1379 | C26: 1727
A27: Lloyd Consumer | B27: 5123 | C27: 3948
A29: BALANCE SHEET
A30: Property, plant & equipment and intangibles | B30: 4745 | C30: 5761
A31: Investments | B31: 74 | C31: 956
A32: Other non-current assets | B32: 158 | C32: 247
A33: Inventories | B33: 4007 | C33: 4398
A34: Trade receivables | B34: 1254 | C34: 782
A35: Cash, equivalents and other bank balances | B35: 3353 | C35: 2351
A36: Other financial assets | B36: 6 | C36: 9
A37: Other current assets | B37: 179 | C37: 221
A38: Total assets | B38: 13775 | C38: 14724
A39: Equity share capital | B39: 63 | C39: 63
A40: Other equity | B40: 8268 | C40: 9414
A41: Lease liabilities - non-current | B41: 241 | C41: 188
... A48: Total equity and liabilities | B48: 13775 | C48: 14724
A50: CASH FLOW
...

Sheet IS
A1: INCOME STATEMENT
A2: INR crore. Format mirrors the company's own investor-update P&L so figures tie directly to the filing.
A3: Note: the FY26 unrealised fair value gain on the Goldi Solar stake (INR 283cr) and the INR 45cr exceptional item are deliberately EXCLUDED. Neither is operating income.
A5: INR crore | B5: FY25A | C5: FY26A | D5: FY27E | E5: FY28E | F5: FY29E | G5: FY30E | H5: FY31E
A7: REVENUE
A9: Switchgears | B9: 2395 | C9: 2585 | D9: =C9*(1+Assumptions!D$7) -> 2817.65 | E9: =D9*(1+Assumptions!E$7) -> 3071.2385 | F9: =E9*(1+Assumptions!F$7) -> 3347.65 | G9: =F9*(1+Assumptions!G$7) -> 3615.462 | H9: =G9*(1+Assumptions!H$7) -> 3904.6989
A10: Cables | B10: 7184 | C10: 8677 | D10: =C10*(1+Assumptions!D$8) -> 9891.78 | E10: =D10*(1+Assumptions!E$8) -> 11177.711 | F10: =E10*(1+Assumptions!F$8) -> 12519.037 | G10: =F10*(1+Assumptions!G$8) -> 13896.131 | H10: =G10*(1+Assumptions!H$8) -> 15285.744
A11: Lighting & Fixtures | B11: 1653 | C11: 1655 | D11: =C11*(1+Assumptions!D$9) -> 1704.65 | E11: =D11*(1+Assumptions!E$9) -> 1772.836 | F11: =E11*(1+Assumptions!F$9) -> 1843.7494 | G11: =F11*(1+Assumptions!G$9) -> 1917.4994 | H11: =G11*(1+Assumptions!H$9) -> 1994.1994
A12: Electrical Consumer Durables | B12: 4011 | C12: 3874 | D12: =C12*(1+Assumptions!D$10) -> 4183.92 | E12: =D12*(1+Assumptions!E$10) -> 4560.4728 | F12: =E12*(1+Assumptions!F$10) -> 4970.9154 | G12: =F12*(1+Assumptions!G$10) -> 5368.5886 | H12: =G12*(1+Assumptions!H$10) -> 5798.0757
A13: Others (incl. solar) | B13: 1379 | C13: 1727 | D13: =C13*(1+Assumptions!D$11) -> 2106.94 | E13: =D13*(1+Assumptions!E$11) -> 2528.328 | F13: =E13*(1+Assumptions!F$11) -> 2983.427 | G13: =F13*(1+Assumptions!G$11) -> 3430.9411 | H13: =G13*(1+Assumptions!H$11) -> 3842.654
A14: Lloyd Consumer | B14: 5123 | C14: 3948 | D14: =C14*(1+Assumptions!D$12) -> 4421.76 | E14: =D14*(1+Assumptions!E$12) -> 5040.8064 | F14: =E14*(1+Assumptions!F$12) -> 5645.7032 | G14: =F14*(1+Assumptions!G$12) -> 6210.2735 | H14: =G14*(1+Assumptions!H$12) -> 6769.1981
A15: Net revenue | B15: =SUM(B9:B14) -> 21745 | C15: =SUM(C9:C14) -> 22466 | D15: =SUM(D9:D14) -> 25126.7 | E15: =SUM(E9:E14) -> 28151.393 | F15: =SUM(F9:F14) -> 31310.482 | G15: =SUM(G9:G14) -> 34438.895 | H15: =SUM(H9:H14) -> 37594.57
A17: CONTRIBUTION
A18: Switchgears | B18: =B9*Assumptions!B$15 -> 907.705 | C18: =C9*Assumptions!C$15 -> 953.865 | D18: =D9*Assumptions!D$15 -> 1048.1658 | E18: =E9*Assumptions!E$15 -> 1151.7144 | F18: =F9*Assumptions!F$15 -> 1255.3687 | G18: =G9*Assumptions!G$15 -> 1355.7982 | H18: =H9*Assumptions!H$15 -> 1464.2621
A19: Cables | B19: =B10*Assumptions!B$16 -> 1012.944 | C19: =C10*Assumptions!C$16 -> 1466.413 | D19: =D10*Assumptions!D$16 -> 1632.1437 | E19: =E10*Assumptions!E$16 -> 1821.967 | F19: =F10*Assumptions!F$16 -> 2028.084 | G19: =G10*Assumptions!G$16 -> 2223.3809 | H19: =H10*Assumptions!H$16 -> 2445.719
A20: Lighting & Fixtures | B20: =B11*Assumptions!B$17 -> 538.878 | C20: =C11*Assumptions!C$17 -> 534.565 | D20: =D11*Assumptions!D$17 -> 528.4415 | E20: =E11*Assumptions!E$17 -> 549.57916 | F20: =F11*Assumptions!F$17 -> 571.56233 | G20: =G11*Assumptions!G$17 -> 594.42482 | H20: =H11*Assumptions!H$17 -> 618.20181
A21: Electrical Consumer Durables | B21: =B12*Assumptions!B$18 -> 954.618 | C21: =C12*Assumptions!C$18 -> 891.02 | D21: =D12*Assumptions!D$18 -> 974.85336 | E21: =E12*Assumptions!E$18 -> 1071.7111 | F21: =F12*Assumptions!F$18 -> 1168.1651 | G21: =G12*Assumptions!G$18 -> 1261.6183 | H21: =H12*Assumptions!H$18 -> 1362.5478
A22: Others (incl. solar) | B22: =B13*Assumptions!B$19 -> 234.43 | C22: =C13*Assumptions!C$19 -> 279.774 | D22: =D13*Assumptions!D$19 -> 347.6451 | E22: =E13*Assumptions!E$19 -> 424.7591 | F22: =F13*Assumptions!F$19 -> 507.1826 | G22: =G13*Assumptions!G$19 -> 583.25999 | H22: =H13*Assumptions!H$19 -> 653.25118
A23: Lloyd Consumer | B23: =B14*Assumptions!B$20 -> 691.605 | C23: =C14*Assumptions!C$20 -> 331.632 | D23: =D14*Assumptions!D$20 -> 442.176 | E23: =E14*Assumptions!E$20 -> 579.69274 | F23: =F14*Assumptions!F$20 -> 705.7129 | G23: =G14*Assumptions!G$20 -> 807.33555 | H23: =H14*Assumptions!H$20 -> 879.99575
A24: Total contribution | B24: =SUM(B18:B23) -> 4340.18 | C24: =SUM(C18:C23) -> 4457.269 | D24: =SUM(D18:D23) -> 4973.4255 | E24: =SUM(E18:E23) -> 5599.4235 | F24: =SUM(F18:F23) -> 6236.0756 | G24: =SUM(G18:G23) -> 6825.8178 | H24: =SUM(H18:H23) -> 7423.9776
A25: as % of net revenue | B25: =B24/B15 -> 0.19959439 | C25: =C24/C15 -> 0.19840065 | D25: =D24/D15 -> 0.19793389 | E25: =E24/E15 -> 0.19890396 | F25: =F24/F15 -> 0.19916895 | G25: =G24/G15 -> 0.19820084 | H25: =H24/H15 -> 0.19747473
A27: Add: depreciation & amortisation | B27: =Schedules!B$8 -> 399 | C27: =Schedules!C$8 -> 429 | D27: =Schedules!D$8 -> 502.534 | E27: =Schedules!E$8 -> 591.17926 | F27: =Schedules!F$8 -> 688.8306 | G27: =Schedules!G$8 -> 757.6557 | H27: =Schedules!H$8 -> 864.67511
A28: Less: advertising & sales promotion | B28: =-B15*Assumptions!B$23 -> -630.605 | C28: =-C15*Assumptions!C$23 -> -606.582 | D28: =-D15*Assumptions!D$23 -> -703.5476 | E28: =-E15*Assumptions!E$23 -> -788.23901 | F28: =-F15*Assumptions!F$23 -> -876.69349 | G28: =-G15*Assumptions!G$23 -> -964.28907 | H28: =-H15*Assumptions!H$23 -> -1052.648
A29: Less: other SG&A | B29: =-B15*Assumptions!B$24 -> -1978.795 | C29: =-C15*Assumptions!C$24 -> -2066.872 | D29: =-D15*Assumptions!D$24 -> -2261.403 | E29: =-E15*Assumptions!E$24 -> -2533.6254 | F29: =-F15*Assumptions!F$24 -> -2817.9434 | G29: =-G15*Assumptions!G$24 -> -3099.5006 | H29: =-H15*Assumptions!H$24 -> -3383.5113
A30: EBITDA | B30: =B24+B27+B28+B29 -> 2129.78 | C30: =C24+C27+C28+C29 -> 2212.815 | D30: =D24+D27+D28+D29 -> 2511.0089 | E30: =E24+E27+E28+E29 -> 2868.7384 | F30: =F24+F27+F28+F29 -> 3230.2694 | G30: =G24+G27+G28+G29 -> 3519.6839 | H30: =H24+H27+H28+H29 -> 3852.4935
A31: EBITDA margin | B31: =B30/B15 -> 0.097943435 | C31: =C30/C15 -> 0.098496172 | D31: =D30/D15 -> 0.099933889 | E31: =E30/E15 -> 0.10190396 | F31: =F30/F15 -> 0.10316895 | G31: =G30/G15 -> 0.10220084 | H31: =H30/H15 -> 0.10247473
A33: Less: depreciation & amortisation | B33: =-Schedules!B$8 -> -399 | C33: =-Schedules!C$8 -> -429 | D33: =-Schedules!D$8 -> -502.534 | E33: =-Schedules!E$8 -> -591.17926 | F33: =-Schedules!F$8 -> -688.8306 | G33: =-Schedules!G$8 -> -757.6557 | H33: =-Schedules!H$8 -> -864.67511
A34: EBIT (clean, operating) | B34: =B30+B33 -> 1730.78 | C34: =C30+C33 -> 1783.815 | D34: =D30+D33 -> 2008.4749 | E34: =E30+E33 -> 2277.5591 | F34: =F30+F33 -> 2541.4388 | G34: =G30+G33 -> 2762.0282 | H34: =H30+H33 -> 2987.8184
A35: EBIT margin | B35: =B34/B15 -> 0.07959439 | C35: =C34/C15 -> 0.07940065 | D35: =D34/D15 -> 0.079933889 | E35: =E34/E15 -> 0.080903958 | F35: =F34/F15 -> 0.081168945 | G35: =G34/G15 -> 0.080200836 | H35: =H34/H15 -> 0.079474732
A37: Add: other income, net | B37: =Assumptions!B$25 -> 259 | C37: =Assumptions!C$25 -> 204 | D37: =Assumptions!D$25 -> 220 | E37: =Assumptions!E$25 -> 240 | F37: =Assumptions!F$25 -> 260 | G37: =Assumptions!G$25 -> 280 | H37: =Assumptions!H$25 -> 300
A38: Less: finance cost (lease interest) | B38: =-Schedules!B$29 -> 0 | C38: =-Schedules!C$29 -> -37 | D38: =-Schedules!D$29 -> -21.2 | E38: =-Schedules!E$29 -> -21.2 | F38: =-Schedules!F$29 -> -21.2 | G38: =-Schedules!G$29 -> -21.2 | H38: =-Schedules!H$29 -> -21.2
A39: Profit before tax | B39: =B34+B37+B38 -> 1989.78 | C39: =C34+C37+C38 -> 1950.815 | D39: =D34+D37+D38 -> 2207.2749 | E39: =E34+E37+E38 -> 2496.3591 | F39: =F34+F37+F38 -> 2780.2388 | G39: =G34+G37+G38 -> 3020.8282 | H39: =H34+H37+H38 -> 3266.6184
A40: Less: tax | B40: =-B39*Assumptions!B$26 -> -515.35302 | C40: =-C39*Assumptions!C$26 -> -456.49071 | D40: =-D39*Assumptions!D$26 -> -556.23326 | E40: =-E39*Assumptions!E$26 -> -629.0825 | F40: =-F39*Assumptions!F$26 -> -700.62017 | G40: =-G39*Assumptions!G$26 -> -761.2487 | H40: =-H39*Assumptions!H$26 -> -823.18783
A41: NET PROFIT | B41: =B39+B40 -> 1474.427 | C41: =C39+C40 -> 1494.3243 | D41: =D39+D40 -> 1651.0416 | E41: =E39+E40 -> 1867.2766 | F41: =F39+F40 -> 2079.6186 | G41: =G39+G40 -> 2259.5795 | H41: =H39+H40 -> 2443.4306
A42: net margin | B42: =B41/B15 -> 0.067805334 | C42: =C41/C15 -> 0.066514924 | D42: =D41/D15 -> 0.065708652 | E42: =E41/E15 -> 0.066329812 | F42: =F41/F15 -> 0.066419246 | G42: =G41/G15 -> 0.065611265 | H42: =H41/H15 -> 0.064994241
A44: Memo: dividends declared | B44: =-B41*Assumptions!B$32 -> -620.73376 | C44: =-C41*Assumptions!C$32 -> -549.91134 | D44: =-D41*Assumptions!D$32 -> -610.88539 | E44: =-E41*Assumptions!E$32 -> -690.89235 | F44: =-F41*Assumptions!F$32 -> -769.45888 | G44: =-G41*Assumptions!G$32 -> -836.04441 | H44: =-H41*Assumptions!H$32 -> -904.06931
A45: Memo: retained earnings for the year | B45: =B41+B44 -> 853.69322 | C45: =C41+C44 -> 944.41295 | D45: =D41+D44 -> 1040.1562 | E45: =E41+E44 -> 1176.3843 | F45: =F41+F44 -> 1310.1597 | G45: =G41+G44 -> 1423.5351 | H45: =H41+H44 -> 1539.3612

Sheet Schedules
A1: SUPPORTING SCHEDULES
A2: Fixed assets, working capital and lease liabilities. Every balance-sheet movement originates here.
A4: INR crore | B4: FY25A | C4: FY26A | D4: FY27E | E4: FY28E | F4: FY29E | G4: FY30E | H4: FY31E
A6: FIXED ASSET (PP&E AND INTANGIBLES) SCHEDULE
A7: Opening net block | C7: 4745 | D7: =C11 -> 5761 | E7: =D11 -> 6514.801 | F7: =E11 -> 7190.4344 | G7: =F11 -> 7754.0231 | H7: =G11 -> 8305.0454
A8: Less: depreciation & amortisation | B8: 399 | C8: 429 | D8: =IS!D$15*Assumptions!D$28 -> 502.534 | E8: =IS!E$15*Assumptions!E$28 -> 591.17926 | F8: =IS!F$15*Assumptions!F$28 -> 688.8306 | G8: =IS!G$15*Assumptions!G$28 -> 757.6557 | H8: =IS!H$15*Assumptions!H$28 -> 864.67511
A9: Add: capital expenditure | C9: 1484 | D9: =IS!D$15*Assumptions!D$27 -> 1256.335 | E9: =IS!E$15*Assumptions!E$27 -> 1266.8127 | F9: =IS!F$15*Assumptions!F$27 -> 1252.4193 | G9: =IS!G$15*Assumptions!G$27 -> 1308.678 | H9: =IS!H$15*Assumptions!H$27 -> 1315.8099
A10: Other movements (disposals, reclassification) | C10: -39 | D10: 0 | E10: 0 | F10: 0 | G10: 0 | H10: 0
A11: Closing net block | C11: =C7-C8+C9+C10 -> 5761 | D11: =D7-D8+D9+D10 -> 6514.801 | E11: =E7-E8+E9+E10 -> 7190.4344 | F11: =F7-F8+F9+F10 -> 7754.0231 | G11: =G7-G8+G9+G10 -> 8305.0454 | H11: =H7-H8+H9+H10 -> 8756.1803
A13: WORKING CAPITAL SCHEDULE | D13: Historical columns are the reported balances, so the FY27 movement ties exactly to the FY26 balance sheet. Forecast columns are driven by the days assumptions.
A14: Inventories | B14: 4007 | C14: 4398 | D14: =IS!D$15*Assumptions!D$29/365 -> 4887.6595 | E14: =IS!E$15*Assumptions!E$29/365 -> 5476.0244 | F14: =IS!F$15*Assumptions!F$29/365 -> 6090.5321 | G14: =IS!G$15*Assumptions!G$29/365 -> 6699.0728 | H14: =IS!H$15*Assumptions!H$29/365 -> 7312.9164
A15: Trade receivables | B15: 1254 | C15: 782 | D15: =IS!D$15*Assumptions!D$30/365 -> 1032.6041 | E15: =IS!E$15*Assumptions!E$30/365 -> 1156.9066 | F15: =IS!F$15*Assumptions!F$30/365 -> 1286.7321 | G15: =IS!G$15*Assumptions!G$30/365 -> 1415.2971 | H15: =IS!H$15*Assumptions!H$30/365 -> 1544.9823
A16: Trade payables | B16: 3040 | C16: 2903 | D16: =IS!D$15*Assumptions!D$31/365 -> 3235.4929 | E16: =IS!E$15*Assumptions!E$31/365 -> 3624.9739 | F16: =IS!F$15*Assumptions!F$31/365 -> 4031.7607 | G16: =IS!G$15*Assumptions!G$31/365 -> 4434.5975 | H16: =IS!H$15*Assumptions!H$31/365 -> 4840.9446
A17: Net working capital | B17: =B14+B15-B16 -> 2221 | C17: =C14+C15-C16 -> 2277 | D17: =D14+D15-D16 -> 2684.7707 | E17: =E14+E15-E16 -> 3007.9571 | F17: =F14+F15-F16 -> 3345.5035 | G17: =G14+G15-G16 -> 3679.7724 | H17: =H14+H15-H16 -> 4016.9541
A18: Increase / (decrease) in net working capital | C18: =C17-B17 -> 56 | D18: =D17-C17 -> 407.77068 | E18: =E17-D17 -> 323.18639 | F18: =F17-E17 -> 337.54646 | G18: =G17-F17 -> 334.26885 | H18: =H17-G17 -> 337.18167
A19: NWC days on net revenue | B19: =B17/IS!B$15*365 -> 37.280524 | C19: =C17/IS!C$15*365 -> 36.993902 | D19: =D17/IS!D$15*365 -> 39 | E19: =E17/IS!E$15*365 -> 39 | F19: =F17/IS!F$15*365 -> 39 | G19: =G17/IS!G$15*365 -> 39 | H19: =H17/IS!H$15*365 -> 39
A22: LEASE LIABILITY SCHEDULE
A23: Havells carries no borrowings. The only debt-like liability on the balance sheet is Ind AS 116 lease liabilities.
A24: SIMPLIFYING ASSUMPTION: principal is held flat, i.e. new leases recognised each year are assumed to offset amortisation of existing ones. Cash lease payments therefore equal interest accretion. At INR 265cr against a market capitalisation near INR 75,000cr this is immaterial, but state it in your memo rather than letting a reader discover it.
A25: Opening lease liability | C25: 319 | D25: =C28 -> 265 | E25: =D28 -> 265 | F25: =E28 -> 265 | G25: =F28 -> 265 | H25: =G28 -> 265
A26: Add: interest accretion (to income statement) | C26: 37 | D26: =D25*Assumptions!D$33 -> 21.2 | E26: =E25*Assumptions!E$33 -> 21.2 | F26: =F25*Assumptions!F$33 -> 21.2 | G26: =G25*Assumptions!G$33 -> 21.2 | H26: =H25*Assumptions!H$33 -> 21.2
A27: Less: lease payments (cash) | C27: 91 | D27: =D26 -> 21.2 | E27: =E26 -> 21.2 | F27: =F26 -> 21.2 | G27: =G26 -> 21.2 | H27: =H26 -> 21.2
A28: Closing lease liability | C28: 265 | D28: =D25+D26-D27 -> 265 | E28: =E25+E26-E27 -> 265 | F28: =F25+F26-F27 -> 265 | G28: =G25+G26-G27 -> 265 | H28: =H25+H26-H27 -> 265
A29: Memo: finance cost to income statement | C29: =C26 -> 37 | D29: =D26 -> 21.2 | E29: =E26 -> 21.2 | F29: =F26 -> 21.2 | G29: =G26 -> 21.2 | H29: =H26 -> 21.2
A30: split: non-current (70%) | C30: 188 | D30: =D28*0.7 -> 185.5 | E30: =E28*0.7 -> 185.5 | F30: =F28*0.7 -> 185.5 | G30: =G28*0.7 -> 185.5 | H30: =H28*0.7 -> 185.5
A31: split: current (30%) | C31: 77 | D31: =D28*0.3 -> 79.5 | E31: =E28*0.3 -> 79.5 | F31: =F28*0.3 -> 79.5 | G31: =G28*0.3 -> 79.5 | H31: =H28*0.3 -> 79.5

Sheet CFS
A1: CASH FLOW STATEMENT
A2: Indirect method. Forecast years only - the historical cash flow is on the Historicals tab.
A4: INR crore | B4: FY25A | C4: FY26A | D4: FY27E | E4: FY28E | F4: FY29E | G4: FY30E | H4: FY31E
A6: OPERATING ACTIVITIES
A7: Net profit | D7: =IS!D$41 -> 1651.0416 | E7: =IS!E$41 -> 1867.2766 | F7: =IS!F$41 -> 2079.6186 | G7: =IS!G$41 -> 2259.5795 | H7: =IS!H$41 -> 2443.4306
A8: Add back: depreciation & amortisation | D8: =Schedules!D$8 -> 502.534 | E8: =Schedules!E$8 -> 591.17926 | F8: =Schedules!F$8 -> 688.8306 | G8: =Schedules!G$8 -> 757.6557 | H8: =Schedules!H$8 -> 864.67511
A9: Less: increase in net working capital | D9: =-Schedules!D$18 -> -407.77068 | E9: =-Schedules!E$18 -> -323.18639 | F9: =-Schedules!F$18 -> -337.54646 | G9: =-Schedules!G$18 -> -334.26885 | H9: =-Schedules!H$18 -> -337.18167
A10: Cash flow from operations | D10: =SUM(D7:D9) -> 1745.8049 | E10: =SUM(E7:E9) -> 2135.2695 | F10: =SUM(F7:F9) -> 2430.9027 | G10: =SUM(G7:G9) -> 2682.9663 | H10: =SUM(H7:H9) -> 2970.924
A12: INVESTING ACTIVITIES
A13: Capital expenditure | D13: =-Schedules!D$9 -> -1256.335 | E13: =-Schedules!E$9 -> -1266.8127 | F13: =-Schedules!F$9 -> -1252.4193 | G13: =-Schedules!G$9 -> -1308.678 | H13: =-Schedules!H$9 -> -1315.8099
A14: Other movements in fixed assets | D14: =-Schedules!D$10 -> 0 | E14: =-Schedules!E$10 -> 0 | F14: =-Schedules!F$10 -> 0 | G14: =-Schedules!G$10 -> 0 | H14: =-Schedules!H$10 -> 0
A15: Cash flow from investing | D15: =SUM(D13:D14) -> -1256.335 | E15: =SUM(E13:E14) -> -1266.8127 | F15: =SUM(F13:F14) -> -1252.4193 | G15: =SUM(G13:G14) -> -1308.678 | H15: =SUM(H13:H14) -> -1315.8099
A17: FINANCING ACTIVITIES
A18: Dividends paid | D18: =IS!D$44 -> -610.88539 | E18: =IS!E$44 -> -690.89235 | F18: =IS!F$44 -> -769.45888 | G18: =IS!G$44 -> -836.04441 | H18: =IS!H$44 -> -904.06931
A19: Cash flow from financing | D19: =D18 -> -610.88539 | E19: =E18 -> -690.89235 | F19: =F18 -> -769.45888 | G19: =G18 -> -836.04441 | H19: =H18 -> -904.06931
A21: Net increase / (decrease) in cash | D21: =D10+D15+D19 -> -121.41548 | E21: =E10+E15+E19 -> 177.56445 | F21: =F10+F15+F19 -> 409.02459 | G21: =G10+G15+G19 -> 538.2439 | H21: =H10+H15+H19 -> 751.04474
A22: Opening cash and bank balances | D22: =C23 -> 2351 | E22: =D23 -> 2229.5845 | F22: =E23 -> 2407.149 | G22: =F23 -> 2816.1736 | H22: =G23 -> 3354.4175
A23: Closing cash and bank balances | C23: 2351 | D23: =D21+D22 -> 2229.5845 | E23: =E21+E22 -> 2407.149 | F23: =F21+F22 -> 2816.1736 | G23: =G21+G22 -> 3354.4175 | H23: =H21+H22 -> 4105.4622

Sheet BS
A1: BALANCE SHEET
A2: The 'Check' row must read zero in every column. A non-zero check means the model is broken.
A4: INR crore | B4: FY25A | C4: FY26A | D4: FY27E | E4: FY28E | F4: FY29E | G4: FY30E | H4: FY31E
A6: ASSETS
A7: Property, plant & equipment and intangibles | B7: 4745 | C7: 5761 | D7: =Schedules!D$11 -> 6514.801 | E7: =Schedules!E$11 -> 7190.4344 | F7: =Schedules!F$11 -> 7754.0231 | G7: =Schedules!G$11 -> 8305.0454 | H7: =Schedules!H$11 -> 8756.1803
A8: Investments | B8: 74 | C8: 956 | D8: =C8 -> 956 | E8: =C8 -> 956 | F8: =C8 -> 956 | G8: =C8 -> 956 | H8: =C8 -> 956
A9: Other non-current assets | B9: 158 | C9: 247 | D9: =C9 -> 247 | E9: =C9 -> 247 | F9: =C9 -> 247 | G9: =C9 -> 247 | H9: =C9 -> 247
A10: Inventories | B10: 4007 | C10: 4398 | D10: =Schedules!D$14 -> 4887.6595 | E10: =Schedules!E$14 -> 5476.0244 | F10: =Schedules!F$14 -> 6090.5321 | G10: =Schedules!G$14 -> 6699.0728 | H10: =Schedules!H$14 -> 7312.9164
A11: Trade receivables | B11: 1254 | C11: 782 | D11: =Schedules!D$15 -> 1032.6041 | E11: =Schedules!E$15 -> 1156.9066 | F11: =Schedules!F$15 -> 1286.7321 | G11: =Schedules!G$15 -> 1415.2971 | H11: =Schedules!H$15 -> 1544.9823
A12: Cash, equivalents and other bank balances | B12: 3353 | C12: 2351 | D12: =CFS!D$23 -> 2229.5845 | E12: =CFS!E$23 -> 2407.149 | F12: =CFS!F$23 -> 2816.1736 | G12: =CFS!G$23 -> 3354.4175 | H12: =CFS!H$23 -> 4105.4622
A13: Other financial assets | B13: 6 | C13: 9 | D13: =C13 -> 9 | E13: =C13 -> 9 | F13: =C13 -> 9 | G13: =C13 -> 9 | H13: =C13 -> 9
A14: Other current assets | B14: 179 | C14: 221 | D14: =C14 -> 221 | E14: =C14 -> 221 | F14: =C14 -> 221 | G14: =C14 -> 221 | H14: =C14 -> 221
A15: TOTAL ASSETS | B15: =SUM(B7:B14) -> 13776 | C15: =SUM(C7:C14) -> 14725 | D15: =SUM(D7:D14) -> 16097.649 | E15: =SUM(E7:E14) -> 17663.514 | F15: =SUM(F7:F14) -> 19380.461 | G15: =SUM(G7:G14) -> 21206.833 | H15: =SUM(H7:H14) -> 23152.541
A17: EQUITY AND LIABILITIES
A18: Equity share capital | B18: 63 | C18: 63 | D18: =C18 -> 63 | E18: =C18 -> 63 | F18: =C18 -> 63 | G18: =C18 -> 63 | H18: =C18 -> 63
A19: Other equity | B19: 8268 | C19: 9414 | D19: =C19+IS!D$45 -> 10454.156 | E19: =D19+IS!E$45 -> 11630.54 | F19: =E19+IS!F$45 -> 12940.7 | G19: =F19+IS!G$45 -> 14364.235 | H19: =G19+IS!H$45 -> 15903.597
A20: Lease liabilities - non-current | B20: 241 | C20: 188 | D20: =Schedules!D$30 -> 185.5 | E20: =Schedules!E$30 -> 185.5 | F20: =Schedules!F$30 -> 185.5 | G20: =Schedules!G$30 -> 185.5 | H20: =Schedules!H$30 -> 185.5
A21: Deferred tax liabilities, net | B21: 375 | C21: 435 | D21: =C21 -> 435 | E21: =C21 -> 435 | F21: =C21 -> 435 | G21: =C21 -> 435 | H21: =C21 -> 435
A22: Other non-current liabilities | B22: 67 | C22: 62 | D22: =C22 -> 62 | E22: =C22 -> 62 | F22: =C22 -> 62 | G22: =C22 -> 62 | H22: =C22 -> 62
A23: Lease liabilities - current | B23: 78 | C23: 77 | D23: =Schedules!D$31 -> 79.5 | E23: =Schedules!E$31 -> 79.5 | F23: =Schedules!F$31 -> 79.5 | G23: =Schedules!G$31 -> 79.5 | H23: =Schedules!H$31 -> 79.5
A24: Trade payables | B24: 3040 | C24: 2903 | D24: =Schedules!D$16 -> 3235.4929 | E24: =Schedules!E$16 -> 3624.9739 | F24: =Schedules!F$16 -> 4031.7607 | G24: =Schedules!G$16 -> 4434.5975 | H24: =Schedules!H$16 -> 4840.9446
A25: Other financial liabilities | B25: 865 | C25: 868 | D25: =C25 -> 868 | E25: =C25 -> 868 | F25: =C25 -> 868 | G25: =C25 -> 868 | H25: =C25 -> 868
A26: Other current liabilities | B26: 778 | C26: 715 | D26: =C26 -> 715 | E26: =C26 -> 715 | F26: =C26 -> 715 | G26: =C26 -> 715 | H26: =C26 -> 715
A27: TOTAL EQUITY AND LIABILITIES | B27: =SUM(B18:B26) -> 13775 | C27: =SUM(C18:C26) -> 14725 | D27: =SUM(D18:D26) -> 16097.649 | E27: =SUM(E18:E26) -> 17663.514 | F27: =SUM(F18:F26) -> 19380.461 | G27: =SUM(G18:G26) -> 21206.833 | H27: =SUM(H18:H26) -> 23152.541
A29: CHECK (must be zero) | B29: =B15-B27 -> 1 | C29: =C15-C27 -> 0 | D29: =D15-D27 -> 0 | E29: =E15-E27 -> 0 | F29: =F15-F27 -> 0 | G29: =G15-G27 -> 0 | H29: =H15-H27 -> 0
A31: The FY25A column reads 1 rather than 0. This is the company's own rounding in the abridged balance sheet it filed, not a model error - the reported totals do not sum exactly. Every forecast column reads zero.

Sheet WACC
A1: WEIGHTED AVERAGE COST OF CAPITAL
A2: Havells carries no borrowings. WACC is therefore close to pure cost of equity. Replace every yellow cell with a figure you pulled yourself, and record the date.
A4: COST OF EQUITY (CAPM)
A5: Risk-free rate (10-year India G-Sec yield) | B5: 0.0702 | C5: SOURCED 11-Sep-2026: India 10Y G-Sec yield, indiamacroindicators.co.in (RBI-referenced benchmark). Update if presenting on a later date.
A6: Levered beta | B6: 0.9 | C6: SOURCED: Equentis stock-screener beta estimate (0.90, describes Havells as "volatility broadly in line with the market"), pulled Sep 2026. Cross-check: scripts/beta_regression.py was not run against a live downloaded price series for this figure -- treat as a third-party estimate, not a self-run regression, and re-run the regression script before final submission if time allows.
A7: Equity risk premium (India) | B7: 0.0731 | C7: SOURCED: Damodaran country equity risk premium table, July 2026 update -- India total ERP (mature-market ERP of 4.17% plus India country risk premium), reported via secondary coverage of the workbook. Verify against the primary source at pages.stern.nyu.edu/~adamodar before final submission.
A8: Cost of equity = Rf + beta x ERP | B8: =B5+B6*B7 -> 0.13599
A10: COST OF DEBT
A11: Pre-tax cost of debt | B11: 0.08 | C11: Implied lease discount rate. Havells has no borrowings, so this is a notional figure.
A12: Marginal tax rate | B12: 0.252 | C12: Indian statutory rate under the concessional regime.
A13: After-tax cost of debt | B13: =B11*(1-B12) -> 0.05984
A15: CAPITAL STRUCTURE
A16: Market value of equity (INR cr) | B16: =Assumptions!B37*Assumptions!B38 -> 70035.9 | C16: Shares x price, both from Assumptions.
A17: Debt: lease liabilities (INR cr) | B17: =Schedules!C28 -> 265 | C17: The only debt-like item on the balance sheet.
A18: Total capital (INR cr) | B18: =B16+B17 -> 70300.9
A19: Weight of equity | B19: =B16/B18 -> 0.99623049
A20: Weight of debt | B20: =B17/B18 -> 0.0037695108
A22: WACC | B22: =B19*B8+B20*B13 -> 0.13570295 | C22: With a debt weight this small, WACC is effectively cost of equity. Say so explicitly in your memo rather than fabricating leverage.

Sheet DCF
A1: DISCOUNTED CASH FLOW - FREE CASH FLOW TO FIRM
A2: FCFF = EBIT x (1 - tax rate) + D&A - capex - increase in net working capital.
A3: EBIT here is CLEAN OPERATING EBIT: it excludes other income, the Goldi Solar fair value gain and exceptional items. Those are handled in the equity bridge instead.
A5: INR crore | D5: FY27E | E5: FY28E | F5: FY29E | G5: FY30E | H5: FY31E
A7: EBIT (clean, operating) | D7: =IS!D$34 -> 2008.4749 | E7: =IS!E$34 -> 2277.5591 | F7: =IS!F$34 -> 2541.4388 | G7: =IS!G$34 -> 2762.0282 | H7: =IS!H$34 -> 2987.8184
A8: Effective tax rate | D8: =Assumptions!D$26 -> 0.252 | E8: =Assumptions!E$26 -> 0.252 | F8: =Assumptions!F$26 -> 0.252 | G8: =Assumptions!G$26 -> 0.252 | H8: =Assumptions!H$26 -> 0.252
A9: NOPAT = EBIT x (1 - t) | D9: =D7*(1-D8) -> 1502.3392 | E9: =E7*(1-E8) -> 1703.6142 | F9: =F7*(1-F8) -> 1900.9962 | G9: =G7*(1-G8) -> 2065.9971 | H9: =H7*(1-H8) -> 2234.8882
A11: Add: depreciation & amortisation | D11: =Schedules!D$8 -> 502.534 | E11: =Schedules!E$8 -> 591.17926 | F11: =Schedules!F$8 -> 688.8306 | G11: =Schedules!G$8 -> 757.6557 | H11: =Schedules!H$8 -> 864.67511
A12: Less: capital expenditure | D12: =-Schedules!D$9 -> -1256.335 | E12: =-Schedules!E$9 -> -1266.8127 | F12: =-Schedules!F$9 -> -1252.4193 | G12: =-Schedules!G$9 -> -1308.678 | H12: =-Schedules!H$9 -> -1315.8099
A13: Less: increase in net working capital | D13: =-Schedules!D$18 -> -407.77068 | E13: =-Schedules!E$18 -> -323.18639 | F13: =-Schedules!F$18 -> -337.54646 | G13: =-Schedules!G$18 -> -334.26885 | H13: =-Schedules!H$18 -> -337.18167
A15: FREE CASH FLOW TO FIRM | D15: =D9+D11+D12+D13 -> 340.76751 | E15: =E9+E11+E12+E13 -> 704.7944 | F15: =F9+F11+F12+F13 -> 999.86108 | G15: =G9+G11+G12+G13 -> 1180.7059 | H15: =H9+H11+H12+H13 -> 1446.5716
A17: Discount period (mid-year convention) | D17: =1-Assumptions!$B$41*0.5 -> 0.5 | E17: =2-Assumptions!$B$41*0.5 -> 1.5 | F17: =3-Assumptions!$B$41*0.5 -> 2.5 | G17: =4-Assumptions!$B$41*0.5 -> 3.5 | H17: =5-Assumptions!$B$41*0.5 -> 4.5
A18: Discount factor | D18: =1/(1+WACC!$B$22)^D17 -> 0.93835597 | E18: =1/(1+WACC!$B$22)^E17 -> 0.82623363 | F18: =1/(1+WACC!$B$22)^F17 -> 0.72750857 | G18: =1/(1+WACC!$B$22)^G17 -> 0.64057998 | H18: =1/(1+WACC!$B$22)^H17 -> 0.56403831
A19: Present value of FCFF | D19: =D15*D18 -> 319.76123 | E19: =E15*E18 -> 582.32484 | F19: =F15*F18 -> 727.4075 | G19: =G15*G18 -> 756.33656 | H19: =H15*H18 -> 815.92183
A22: VALUATION BRIDGE
A23: Sum of PV of explicit forecast FCFF | B23: =SUM(D19:H19) -> 3201.752
A24: Terminal value (Gordon growth) | B24: =H15*(1+Assumptions!$B$39)/(WACC!$B$22-Assumptions!$B$39) -> 17722.846 | D24: TV = final-year FCFF x (1+g) / (WACC - g)
A25: PV of terminal value | B25: =B24*H18 -> 9996.3642
A26: ENTERPRISE VALUE | B26: =B23+B25 -> 13198.116
A27: terminal value as % of enterprise value | B27: =B25/B26 -> 0.75740841 | D27: If this is above 75%, say so openly in your memo. It is the standard criticism of any DCF.
A29: Add: cash, equivalents and bank balances | B29: =BS!C12 -> 2351 | D29: FY26 closing balance.
A30: Less: lease liabilities (debt-like) | B30: =-Schedules!C28 -> -265
A31: Add: non-core investments | B31: =Assumptions!$B$40 -> 883 | D31: Goldi Solar stake at carrying value, since its earnings were excluded from EBIT.
A32: EQUITY VALUE | B32: =B26+B29+B30+B31 -> 16167.116
A33: Diluted shares outstanding (crore) | B33: =Assumptions!$B$37 -> 62.7
A34: INTRINSIC VALUE PER SHARE (INR) | B34: =B32/B33 -> 257.84874
A35: Current market price (INR) | B35: =Assumptions!$B$38 -> 1117
A36: Implied upside / (downside) | B36: =B34/B35-1 -> -0.76915959 | D36: If this is wildly positive, re-examine your assumptions before you conclude the market is wrong.

Sheet Sensitivity
A1: SENSITIVITY ANALYSIS
A2: Intrinsic value per share (INR). Each cell fully re-discounts the explicit forecast and rebuilds terminal value at the stated WACC and g.
A4: WACC (columns) vs terminal growth g (rows)
B6: g \ WACC | C6: =WACC!$B$22+-0.02 -> 0.11570295 | D6: =WACC!$B$22+-0.01 -> 0.12570295 | E6: =WACC!$B$22+0 -> 0.13570295 | F6: =WACC!$B$22+0.01 -> 0.14570295 | G6: =WACC!$B$22+0.02 -> 0.15570295
B7: =Assumptions!$B$39+-0.01 -> 0.04 | C7: =IF((WACC!$B$22+-0.02)<=(Assumptions!$B$39+-0.01),NA(),(SUMPRODUCT(DCF!$D$15:$H$15,(1+(WACC!$B$22+-0.02))^-DCF!$D$17:$H$17)+DCF!$H$15*(1+(Assumptions!$B$39+-0.01))/((WACC!$B$22+-0.02)-(Assumptions!$B$39+-0.01))*(1+(WACC!$B$22+-0.02))^-DCF!$H$17+BS!$C$12-Schedules!$C$28+Assumptions!$B$40)/Assumptions!$B$37) -> 294.7505 | D7: =IF((WACC!$B$22+-0.01)<=(Assumptions!$B$39+-0.01),NA(),(SUMPRODUCT(DCF!$D$15:$H$15,(1+(WACC!$B$22+-0.01))^-DCF!$D$17:$H$17)+DCF!$H$15*(1+(Assumptions!$B$39+-0.01))/((WACC!$B$22+-0.01)-(Assumptions!$B$39+-0.01))*(1+(WACC!$B$22+-0.01))^-DCF!$H$17+BS!$C$12-Schedules!$C$28+Assumptions!$B$40)/Assumptions!$B$37) -> 264.05538 | E7: =IF((WACC!$B$22+0)<=(Assumptions!$B$39+-0.01),NA(),(SUMPRODUCT(DCF!$D$15:$H$15,(1+(WACC!$B$22+0))^-DCF!$D$17:$H$17)+DCF!$H$15*(1+(Assumptions!$B$39+-0.01))/((WACC!$B$22+0)-(Assumptions!$B$39+-0.01))*(1+(WACC!$B$22+0))^-DCF!$H$17+BS!$C$12-Schedules!$C$28+Assumptions!$B$40)/Assumptions!$B$37) -> 239.82999 | F7: =IF((WACC!$B$22+0.01)<=(Assumptions!$B$39+-0.01),NA(),(SUMPRODUCT(DCF!$D$15:$H$15,(1+(WACC!$B$22+0.01))^-DCF!$D$17:$H$17)+DCF!$H$15*(1+(Assumptions!$B$39+-0.01))/((WACC!$B$22+0.01)-(Assumptions!$B$39+-0.01))*(1+(WACC!$B$22+0.01))^-DCF!$H$17+BS!$C$12-Schedules!$C$28+Assumptions!$B$40)/Assumptions!$B$37) -> 220.23608 | G7: =IF((WACC!$B$22+0.02)<=(Assumptions!$B$39+-0.01),NA(),(SUMPRODUCT(DCF!$D$15:$H$15,(1+(WACC!$B$22+0.02))^-DCF!$D$17:$H$17)+DCF!$H$15*(1+(Assumptions!$B$39+-0.01))/((WACC!$B$22+0.02)-(Assumptions!$B$39+-0.01))*(1+(WACC!$B$22+0.02))^-DCF!$H$17+BS!$C$12-Schedules!$C$28+Assumptions!$B$40)/Assumptions!$B$37) -> 204.07097
B8: =Assumptions!$B$39+-0.005 -> 0.045 | C8: =IF((WACC!$B$22+-0.02)<=(Assumptions!$B$39+-0.005),NA(),(SUMPRODUCT(DCF!$D$15:$H$15,(1+(WACC!$B$22+-0.02))^-DCF!$D$17:$H$17)+DCF!$H$15*(1+(Assumptions!$B$39+-0.005))/((WACC!$B$22+-0.02)-(Assumptions!$B$39+-0.005))*(1+(WACC!$B$22+-0.02))^-DCF!$H$17+BS!$C$12-Schedules!$C$28+Assumptions!$B$40)/Assumptions!$B$37) -> 309.4422 | D8: =IF((WACC!$B$22+-0.01)<=(Assumptions!$B$39+-0.005),NA(),(SUMPRODUCT(DCF!$D$15:$H$15,(1+(WACC!$B$22+-0.01))^-DCF!$D$17:$H$17)+DCF!$H$15*(1+(Assumptions!$B$39+-0.005))/((WACC!$B$22+-0.01)-(Assumptions!$B$39+-0.005))*(1+(WACC!$B$22+-0.01))^-DCF!$H$17+BS!$C$12-Schedules!$C$28+Assumptions!$B$40)/Assumptions!$B$37) -> 275.07518 | E8: =IF((WACC!$B$22+0)<=(Assumptions!$B$39+-0.005),NA(),(SUMPRODUCT(DCF!$D$15:$H$15,(1+(WACC!$B$22+0))^-DCF!$D$17:$H$17)+DCF!$H$15*(1+(Assumptions!$B$39+-0.005))/((WACC!$B$22+0)-(Assumptions!$B$39+-0.005))*(1+(WACC!$B$22+0))^-DCF!$H$17+BS!$C$12-Schedules!$C$28+Assumptions!$B$40)/Assumptions!$B$37) -> 248.34273 | F8: =IF((WACC!$B$22+0.01)<=(Assumptions!$B$39+-0.005),NA(),(SUMPRODUCT(DCF!$D$15:$H$15,(1+(WACC!$B$22+0.01))^-DCF!$D$17:$H$17)+DCF!$H$15*(1+(Assumptions!$B$39+-0.005))/((WACC!$B$22+0.01)-(Assumptions!$B$39+-0.005))*(1+(WACC!$B$22+0.01))^-DCF!$H$17+BS!$C$12-Schedules!$C$28+Assumptions!$B$40)/Assumptions!$B$37) -> 226.96834 | G8: =IF((WACC!$B$22+0.02)<=(Assumptions!$B$39+-0.005),NA(),(SUMPRODUCT(DCF!$D$15:$H$15,(1+(WACC!$B$22+0.02))^-DCF!$D$17:$H$17)+DCF!$H$15*(1+(Assumptions!$B$39+-0.005))/((WACC!$B$22+0.02)-(Assumptions!$B$39+-0.005))*(1+(WACC!$B$22+0.02))^-DCF!$H$17+BS!$C$12-Schedules!$C$28+Assumptions!$B$40)/Assumptions!$B$37) -> 209.49819
B9: =Assumptions!$B$39+0 -> 0.05 | C9: =IF((WACC!$B$22+-0.02)<=(Assumptions!$B$39+0),NA(),(SUMPRODUCT(DCF!$D$15:$H$15,(1+(WACC!$B$22+-0.02))^-DCF!$D$17:$H$17)+DCF!$H$15*(1+(Assumptions!$B$39+0))/((WACC!$B$22+-0.02)-(Assumptions!$B$39+0))*(1+(WACC!$B$22+-0.02))^-DCF!$H$17+BS!$C$12-Schedules!$C$28+Assumptions!$B$40)/Assumptions!$B$37) -> 326.36997 | D9: =IF((WACC!$B$22+-0.01)<=(Assumptions!$B$39+0),NA(),(SUMPRODUCT(DCF!$D$15:$H$15,(1+(WACC!$B$22+-0.01))^-DCF!$D$17:$H$17)+DCF!$H$15*(1+(Assumptions!$B$39+0))/((WACC!$B$22+-0.01)-(Assumptions!$B$39+0))*(1+(WACC!$B$22+-0.01))^-DCF!$H$17+BS!$C$12-Schedules!$C$28+Assumptions!$B$40)/Assumptions!$B$37) -> 287.55065 | E9: =IF((WACC!$B$22+0)<=(Assumptions!$B$39+0),NA(),(SUMPRODUCT(DCF!$D$15:$H$15,(1+(WACC!$B$22+0))^-DCF!$D$17:$H$17)+DCF!$H$15*(1+(Assumptions!$B$39+0))/((WACC!$B$22+0)-(Assumptions!$B$39+0))*(1+(WACC!$B$22+0))^-DCF!$H$17+BS!$C$12-Schedules!$C$28+Assumptions!$B$40)/Assumptions!$B$37) -> 257.84874 | F9: =IF((WACC!$B$22+0.01)<=(Assumptions!$B$39+0),NA(),(SUMPRODUCT(DCF!$D$15:$H$15,(1+(WACC!$B$22+0.01))^-DCF!$D$17:$H$17)+DCF!$H$15*(1+(Assumptions!$B$39+0))/((WACC!$B$22+0.01)-(Assumptions!$B$39+0))*(1+(WACC!$B$22+0.01))^-DCF!$H$17+BS!$C$12-Schedules!$C$28+Assumptions!$B$40)/Assumptions!$B$37) -> 234.40406 | G9: =IF((WACC!$B$22+0.02)<=(Assumptions!$B$39+0),NA(),(SUMPRODUCT(DCF!$D$15:$H$15,(1+(WACC!$B$22+0.02))^-DCF!$D$17:$H$17)+DCF!$H$15*(1+(Assumptions!$B$39+0))/((WACC!$B$22+0.02)-(Assumptions!$B$39+0))*(1+(WACC!$B$22+0.02))^-DCF!$H$17+BS!$C$12-Schedules!$C$28+Assumptions!$B$40)/Assumptions!$B$37) -> 215.43884
B10: =Assumptions!$B$39+0.005 -> 0.055 | C10: =IF((WACC!$B$22+-0.02)<=(Assumptions!$B$39+0.005),NA(),(SUMPRODUCT(DCF!$D$15:$H$15,(1+(WACC!$B$22+-0.02))^-DCF!$D$17:$H$17)+DCF!$H$15*(1+(Assumptions!$B$39+0.005))/((WACC!$B$22+-0.02)-(Assumptions!$B$39+0.005))*(1+(WACC!$B$22+-0.02))^-DCF!$H$17+BS!$C$12-Schedules!$C$28+Assumptions!$B$40)/Assumptions!$B$37) -> 346.08638 | D10: =IF((WACC!$B$22+-0.01)<=(Assumptions!$B$39+0.005),NA(),(SUMPRODUCT(DCF!$D$15:$H$15,(1+(WACC!$B$22+-0.01))^-DCF!$D$17:$H$17)+DCF!$H$15*(1+(Assumptions!$B$39+0.005))/((WACC!$B$22+-0.01)-(Assumptions!$B$39+0.005))*(1+(WACC!$B$22+-0.01))^-DCF!$H$17+BS!$C$12-Schedules!$C$28+Assumptions!$B$40)/Assumptions!$B$37) -> 301.79061 | E10: =IF((WACC!$B$22+0)<=(Assumptions!$B$39+0.005),NA(),(SUMPRODUCT(DCF!$D$15:$H$15,(1+(WACC!$B$22+0))^-DCF!$D$17:$H$17)+DCF!$H$15*(1+(Assumptions!$B$39+0.005))/((WACC!$B$22+0)-(Assumptions!$B$39+0.005))*(1+(WACC!$B$22+0))^-DCF!$H$17+BS!$C$12-Schedules!$C$28+Assumptions!$B$40)/Assumptions!$B$37) -> 268.53266 | F10: =IF((WACC!$B$22+0.01)<=(Assumptions!$B$39+0.005),NA(),(SUMPRODUCT(DCF!$D$15:$H$15,(1+(WACC!$B$22+0.01))^-DCF!$D$17:$H$17)+DCF!$H$15*(1+(Assumptions!$B$39+0.005))/((WACC!$B$22+0.01)-(Assumptions!$B$39+0.005))*(1+(WACC!$B$22+0.01))^-DCF!$H$17+BS!$C$12-Schedules!$C$28+Assumptions!$B$40)/Assumptions!$B$37) -> 242.65956 | G10: =IF((WACC!$B$22+0.02)<=(Assumptions!$B$39+0.005),NA(),(SUMPRODUCT(DCF!$D$15:$H$15,(1+(WACC!$B$22+0.02))^-DCF!$D$17:$H$17)+DCF!$H$15*(1+(Assumptions!$B$39+0.005))/((WACC!$B$22+0.02)-(Assumptions!$B$39+0.005))*(1+(WACC!$B$22+0.02))^-DCF!$H$17+BS!$C$12-Schedules!$C$28+Assumptions!$B$40)/Assumptions!$B$37) -> 221.96942
B11: =Assumptions!$B$39+0.01 -> 0.06 | C11: =IF((WACC!$B$22+-0.02)<=(Assumptions!$B$39+0.01),NA(),(SUMPRODUCT(DCF!$D$15:$H$15,(1+(WACC!$B$22+-0.02))^-DCF!$D$17:$H$17)+DCF!$H$15*(1+(Assumptions!$B$39+0.01))/((WACC!$B$22+-0.02)-(Assumptions!$B$39+0.01))*(1+(WACC!$B$22+-0.02))^-DCF!$H$17+BS!$C$12-Schedules!$C$28+Assumptions!$B$40)/Assumptions!$B$37) -> 369.34234 | D11: =IF((WACC!$B$22+-0.01)<=(Assumptions!$B$39+0.01),NA(),(SUMPRODUCT(DCF!$D$15:$H$15,(1+(WACC!$B$22+-0.01))^-DCF!$D$17:$H$17)+DCF!$H$15*(1+(Assumptions!$B$39+0.01))/((WACC!$B$22+-0.01)-(Assumptions!$B$39+0.01))*(1+(WACC!$B$22+-0.01))^-DCF!$H$17+BS!$C$12-Schedules!$C$28+Assumptions!$B$40)/Assumptions!$B$37) -> 318.19789 | E11: =IF((WACC!$B$22+0)<=(Assumptions!$B$39+0.01),NA(),(SUMPRODUCT(DCF!$D$15:$H$15,(1+(WACC!$B$22+0))^-DCF!$D$17:$H$17)+DCF!$H$15*(1+(Assumptions!$B$39+0.01))/((WACC!$B$22+0)-(Assumptions!$B$39+0.01))*(1+(WACC!$B$22+0))^-DCF!$H$17+BS!$C$12-Schedules!$C$28+Assumptions!$B$40)/Assumptions!$B$37) -> 280.62787 | F11: =IF((WACC!$B$22+0.01)<=(Assumptions!$B$39+0.01),NA(),(SUMPRODUCT(DCF!$D$15:$H$15,(1+(WACC!$B$22+0.01))^-DCF!$D$17:$H$17)+DCF!$H$15*(1+(Assumptions!$B$39+0.01))/((WACC!$B$22+0.01)-(Assumptions!$B$39+0.01))*(1+(WACC!$B$22+0.01))^-DCF!$H$17+BS!$C$12-Schedules!$C$28+Assumptions!$B$40)/Assumptions!$B$37) -> 251.87833 | G11: =IF((WACC!$B$22+0.02)<=(Assumptions!$B$39+0.01),NA(),(SUMPRODUCT(DCF!$D$15:$H$15,(1+(WACC!$B$22+0.02))^-DCF!$D$17:$H$17)+DCF!$H$15*(1+(Assumptions!$B$39+0.01))/((WACC!$B$22+0.02)-(Assumptions!$B$39+0.01))*(1+(WACC!$B$22+0.02))^-DCF!$H$17+BS!$C$12-Schedules!$C$28+Assumptions!$B$40)/Assumptions!$B$37) -> 229.18237
B14: Current market price | C14: =Assumptions!$B$38 -> 1117
B15: Base case intrinsic value | C15: =DCF!$B$34 -> 257.84874
A18: REVERSE DCF
A19: Hold WACC and g fixed, then use Excel's Goal Seek (Data > What-If Analysis > Goal Seek) to solve for the segment growth or contribution margin
A20: assumptions that make DCF!B34 equal the current market price. Then write one paragraph on whether those implied assumptions are achievable.
A21: This is the most defensible thing in the whole model. A DCF that disagrees with the market is only interesting once you can say WHAT the market is assuming.
